Workbook
Name YPL1: Couverture!$J$14

Sheet Couverture
G12: [Business plan]
G13: PROGRAMME GO SIYAHA | J13: Edition
J14: 2026
G15: Soutien à l'investissement de croissance
G19: =Synthèse!D9 -> 1111
G20: =IF(ISBLANK(Synthèse!D10),"",Synthèse!D10) -> MaSociété
G21: =IF(Bilan!A3="Equilibré","","Merci de checker l'équilibre de votre bilan")
G22: =IF('Mode de financement'!$A$3="Cohérent","","Merci de checker la cohérence de votre plan de financement (Mode de financement)")&IF('Synthèse du PI'!$A$3="Cohérent","","ainsi que la cohérence du financement de votre PI (Synthèse du PI)")
B27: RAPP-20/MPS-MT-01/V03/23022026
B28: © 2025 Deloitte Financial Advisory - Membre de Deloitte Touche Tohmatsu Limited.

Sheet ANPMExpert
B2: ANPMExpert | Votre nouvel assistant virtuel
B5: Bonjour Madame, Monsieur, Je m'appelle ANPMExpert, et j'ai le plaisir de vous assister afin de bien renseigner votre nouveau modèle du business plan ISTITMAR. Avant de commencer, il me semble pertinent de présenter la légende qui devrait faciliter la préparation de votre business plan :
D6: Cellule à renseigner par vos soins.
D7: Cellule calculée, aucune intervention n'est sollicitée.
D8: Cellule calculée, aucune intervention n'est sollicitée.
D9: Cellule contenant une indication, il suffit de mettre le curseur sur la cellule pour apercevoir le commentaire.
D10: Cellule de commentaire préliminaire qui présente des rappels d'information en lien avec le tableau concerné.
B12: Je tiens également à souligner ces indications clefs pour mieux manipuler le présent modèle du BP :
B13: > Merci de ne pas ajouter/supprimer des feuilles, lignes et/ou colonnes du présent modèle afin de préserver sa consistance.
B14: > Je vous recommande fortement de renseigner soigneusement la "Synthèse" préalablement à toute autre section du présent support.
B15: > Avant de transmettre votre BP sur la plateforme JISR AL-MOKAWALA, vérifiez si la "Couverture" du présent modèle affiche un/des message(s) d'erreurs.
B16: > La protection des feuilles a été instaurée pour garantir la fiabilité des élèments fournis, il est primordiale de ne pas procéder au décryptage des feuilles et/ou modèle.
B17: > Veiller à respecter l'unité de chaque cellule/tableau avant de procéder à l'introduction des réponses/chiffres (e.g., les états financiers sont à présenter en KMAD).
B18: > Il est préférable de présenter le maximum possible de détail (saisie par ligne de facture,fournisseurs, numéro du justificatif..) au niveau de votre détail du PI.
B19: > Il faut obligatoirement renseigner (en sus du CPC prévisionnel) le CPC projet afin de permettre au modèle de procéder aux calculs nécessaires.
B20: > Merci de noter que les feuilles marquées en noir ne nécessitent pas d'intervention de votre part.
B21: > En cas de blocage, n'hésitez pas à adresser votre problème technique (explication et capture d'écran) via votre espace candidature JISR AL-MOKAWALA.
B23: En guise de conclusion, je tiens à rappeler qu'une lecture approfondie du règlement fourni est primordiale avant de vous lancer dans la préparation de votre business plan.
B25: ANPMExpert

Sheet Synthèse
A1: =Couverture!G20 -> MaSociété
A2: =IFERROR(MID(CELL("filename",A2),FIND("]",CELL("filename",A2))+1,255),"< - >") -> Synthèse
B5: > Synthèse du projet <
B7: FEUILLE D’IDENTITÉ
B9: Identifiant | D9: 1111
B10: Raison sociale | D10: MaSociété
B11: Capital social (en MAD)
B12: Activité
B13: A spécifier si autre
B14: Partenaire financier
B16: PROJET DE DEVELOPPEMENT
B18: Objectif du projet | D18: Création
B19: Nature du projet de développement
B20: Ville
B21: Planning de réalisation
B22: Date prévue de démarrage
B23: Investissement total (en MAD) | D23: ='Synthèse du PI'!L23*1000 -> 0
B25: FINANCEMENT DU PROJET
B27: Autofinancement (en MAD) | D27: ='Mode de financement'!G16*1000 -> 0
B28: Crédit bancaire - CMT (en MAD) | D28: =+'Mode de financement'!H16*1000 -> 0
B29: Leasing - Crédit bail (en MAD) | D29: ='Mode de financement'!K16*1000 -> 0
B30: Crédit fournisseur (en MAD) | D30: ='Mode de financement'!J16*1000 -> 0
B31: Financement Participatif (en MAD) | D31: ='Mode de financement'!I16*1000 -> 0
B32: Prime ISTITMAR (en MAD) | D32: ='Mode de financement'!L16*1000 -> 0

Sheet Détail du PI
A1: =Couverture!G20 -> MaSociété
A2: =IFERROR(MID(CELL("filename",A2),FIND("]",CELL("filename",A2))+1,255),"< - >") -> Détail du PI
B6: ANPMExpert: > Il est necessaire de renseigner le montant TTC selon le taux de TVA appliqué. Par défaut, le taux de 20% est appliqué à certaines rubriques; > Merci de noter que certains biens importés sont exonérés de la TVA pour les entreprises en amorçage (cf. loi de finance 2024). Dans le cas d'exonération, merci de reprendre les montants HT au niveau du montant TTC; > Essayez de présenter le détail des justificatifs afin de fournir le maximum de détail sur la composition de chaque pièce justificative.
B14: DETAIL DU PROGRAMME D'INVESTISSEMENT
B16: Année | C16: Nature de l'investissement | D16: Etat du bien | F16: Justificatifs | G16: Référence du justificatif | H16: Date de la pièce | I16: Fournisseur | K16: Montant HT - en devise d'origine - | L16: Devise | M16: Taux de référence | N16: Montant HT - en MAD - | O16: Taux de TVA | P16: Montant TTC - en MAD -
B18: Terrain | K18: Montant HT (en devise) | L18: Devise | M18: Taux | N18: Montant HT (en MAD) | O18: Taux de TVA | P18: Montant TTC (en MAD)
L20: MAD | M20: =VLOOKUP(L20,'1 (A ne pas supprimer)'!$C$29:$D$34,2,FALSE) -> 1 | N20: =M20*K20 -> 0 | O20: 0 | P20: =N20*(1+O20) -> 0
L21: MAD | M21: =VLOOKUP(L21,'1 (A ne pas supprimer)'!$C$29:$D$34,2,FALSE) -> 1 | N21: =M21*K21 -> 0 | O21: 0 | P21: =N21*(1+O21) -> 0
L22: MAD | M22: =VLOOKUP(L22,'1 (A ne pas supprimer)'!$C$29:$D$34,2,FALSE) -> 1 | N22: =M22*K22 -> 0 | O22: 0 | P22: =N22*(1+O22) -> 0
L23: MAD | M23: =VLOOKUP(L23,'1 (A ne pas supprimer)'!$C$29:$D$34,2,FALSE) -> 1 | N23: =M23*K23 -> 0 | O23: 0 | P23: =N23*(1+O23) -> 0
L24: MAD | M24: =VLOOKUP(L24,'1 (A ne pas supprimer)'!$C$29:$D$34,2,FALSE) -> 1 | N24: =M24*K24 -> 0 | O24: 0 | P24: =N24*(1+O24) -> 0
L25: MAD | M25: =VLOOKUP(L25,'1 (A ne pas supprimer)'!$C$29:$D$34,2,FALSE) -> 1 | N25: =M25*K25 -> 0 | O25: 0 | P25: =N25*(1+O25) -> 0
L26: MAD | M26: =VLOOKUP(L26,'1 (A ne pas supprimer)'!$C$29:$D$34,2,FALSE) -> 1 | N26: =M26*K26 -> 0 | O26: 0 | P26: =N26*(1+O26) -> 0
L27: MAD | M27: =VLOOKUP(L27,'1 (A ne pas supprimer)'!$C$29:$D$34,2,FALSE) -> 1 | N27: =M27*K27 -> 0 | O27: 0 | P27: =N27*(1+O27) -> 0
L28: MAD | M28: =VLOOKUP(L28,'1 (A ne pas supprimer)'!$C$29:$D$34,2,FALSE) -> 1 | N28: =M28*K28 -> 0 | O28: 0 | P28: =N28*(1+O28) -> 0
L29: MAD | M29: =VLOOKUP(L29,'1 (A ne pas supprimer)'!$C$29:$D$34,2,FALSE) -> 1 | N29: =M29*K29 -> 0 | O29: 0 | P29: =N29*(1+O29) -> 0
L30: MAD | M30: =VLOOKUP(L30,'1 (A ne pas supprimer)'!$C$29:$D$34,2,FALSE) -> 1 | N30: =M30*K30 -> 0 | O30: 0 | P30: =N30*(1+O30) -> 0
L31: MAD | M31: =VLOOKUP(L31,'1 (A ne pas supprimer)'!$C$29:$D$34,2,FALSE) -> 1 | N31: =M31*K31 -> 0 | O31: 0 | P31: =N31*(1+O31) -> 0
... L54: MAD | M54: =VLOOKUP(L54,'1 (A ne pas supprimer)'!$C$29:$D$34,2,FALSE) -> 1 | N54: =M54*K54 -> 0 | O54: 0 | P54: =N54*(1+O54) -> 0
B56: Total - Terrain | N56: =SUM(N20:N54) -> 0 | P56: =SUM(P20:P54) -> 0
B58: Constructions | K58: Montant HT (en devise) | L58: Devise | M58: Taux | N58: Montant HT (en MAD) | O58: Taux de TVA | P58: Montant TTC (en MAD)
L60: MAD | M60: =VLOOKUP(L60,'1 (A ne pas supprimer)'!$C$29:$D$34,2,FALSE) -> 1 | N60: =M60*K60 -> 0 | O60: 0.2 | P60: =N60*(1+O60) -> 0
L61: MAD | M61: =VLOOKUP(L61,'1 (A ne pas supprimer)'!$C$29:$D$34,2,FALSE) -> 1 | N61: =M61*K61 -> 0 | O61: 0.2 | P61: =N61*(1+O61) -> 0
L62: MAD | M62: =VLOOKUP(L62,'1 (A ne pas supprimer)'!$C$29:$D$34,2,FALSE) -> 1 | N62: =M62*K62 -> 0 | O62: 0.2 | P62: =N62*(1+O62) -> 0
L63: MAD | M63: =VLOOKUP(L63,'1 (A ne pas supprimer)'!$C$29:$D$34,2,FALSE) -> 1 | N63: =M63*K63 -> 0 | O63: 0.2 | P63: =N63*(1+O63) -> 0
L64: MAD | M64: =VLOOKUP(L64,'1 (A ne pas supprimer)'!$C$29:$D$34,2,FALSE) -> 1 | N64: =M64*K64 -> 0 | O64: 0.2 | P64: =N64*(1+O64) -> 0
L65: MAD | M65: =VLOOKUP(L65,'1 (A ne pas supprimer)'!$C$29:$D$34,2,FALSE) -> 1 | N65: =M65*K65 -> 0 | O65: 0.2 | P65: =N65*(1+O65) -> 0
L66: MAD | M66: =VLOOKUP(L66,'1 (A ne pas supprimer)'!$C$29:$D$34,2,FALSE) -> 1 | N66: =M66*K66 -> 0 | O66: 0.2 | P66: =N66*(1+O66) -> 0
L67: MAD | M67: =VLOOKUP(L67,'1 (A ne pas supprimer)'!$C$29:$D$34,2,FALSE) -> 1 | N67: =M67*K67 -> 0 | O67: 0.2 | P67: =N67*(1+O67) -> 0
L68: MAD | M68: =VLOOKUP(L68,'1 (A ne pas supprimer)'!$C$29:$D$34,2,FALSE) -> 1 | N68: =M68*K68 -> 0 | O68: 0.2 | P68: =N68*(1+O68) -> 0
L69: MAD | M69: =VLOOKUP(L69,'1 (A ne pas supprimer)'!$C$29:$D$34,2,FALSE) -> 1 | N69: =M69*K69 -> 0 | O69: 0.2 | P69: =N69*(1+O69) -> 0
L70: MAD | M70: =VLOOKUP(L70,'1 (A ne pas supprimer)'!$C$29:$D$34,2,FALSE) -> 1 | N70: =M70*K70 -> 0 | O70: 0.2 | P70: =N70*(1+O70) -> 0
L71: MAD | M71: =VLOOKUP(L71,'1 (A ne pas supprimer)'!$C$29:$D$34,2,FALSE) -> 1 | N71: =M71*K71 -> 0 | O71: 0.2 | P71: =N71*(1+O71) -> 0
... L109: MAD | M109: =VLOOKUP(L109,'1 (A ne pas supprimer)'!$C$29:$D$34,2,FALSE) -> 1 | N109: =M109*K109 -> 0 | O109: 0.2 | P109: =N109*(1+O109) -> 0
B111: Total - Constructions | N111: =SUM(N60:N109) -> 0 | P111: =SUM(P60:P109) -> 0
B113: Aménagement et agencement | K113: Montant HT (en devise) | L113: Devise | M113: Taux | N113: Montant HT (en MAD) | O113: Taux de TVA | P113: Montant TTC (en MAD)
L115: MAD | M115: =VLOOKUP(L115,'1 (A ne pas supprimer)'!$C$29:$D$34,2,FALSE) -> 1 | N115: =M115*K115 -> 0 | O115: 0.2 | P115: =N115*(1+O115) -> 0
L116: MAD | M116: =VLOOKUP(L116,'1 (A ne pas supprimer)'!$C$29:$D$34,2,FALSE) -> 1 | N116: =M116*K116 -> 0 | O116: 0.2 | P116: =N116*(1+O116) -> 0
L117: MAD | M117: =VLOOKUP(L117,'1 (A ne pas supprimer)'!$C$29:$D$34,2,FALSE) -> 1 | N117: =M117*K117 -> 0 | O117: 0.2 | P117: =N117*(1+O117) -> 0
L118: MAD | M118: =VLOOKUP(L118,'1 (A ne pas supprimer)'!$C$29:$D$34,2,FALSE) -> 1 | N118: =M118*K118 -> 0 | O118: 0.2 | P118: =N118*(1+O118) -> 0
...

Sheet Synthèse du PI
A1: =Couverture!G20 -> MaSociété
A2: =IFERROR(MID(CELL("filename",A2),FIND("]",CELL("filename",A2))+1,255),"< - >") -> Synthèse du PI
A3: =IF(AND(ABS(E44)<1,ABS(F44)<1,ABS(G44)<1,ABS(H44)<1,ABS(L31)<1,ABS(L32)<1,ABS(L33)<1,ABS(L34)<1,ABS(L36)<1,ABS(L37)<1),"Cohérent","Non cohérent") -> Cohérent
B5: ANPMExpert: > Il est necessaire de renseigner le financement du PI en respectant les plafonds de chaque mode de financement conformément au règlement d'appel à projets.
B12: SYNTHESE DU PROGRAMME D'INVESTISSEMENT
B14: PROGRAMME D'INVESTISSEMENT - PI (en KMAD) | E14: =_xlfn.NUMBERVALUE(YPL1) -> 2026 | F14: =E14+1 -> 2027 | G14: =F14+1 -> 2028 | H14: =+G14+1 -> 2029 | I14: =H14+1 -> 2030 | J14: Total HT | L14: Total TTC | M14: % Poids
B16: Frais préliminaires | E16: =(SUMIFS('Détail du PI'!$N$326:$N$345,'Détail du PI'!$B$326:$B$345,E$14)) / 1000 -> 0 | F16: =(SUMIFS('Détail du PI'!$N$326:$N$345,'Détail du PI'!$B$326:$B$345,F$14)) / 1000 -> 0 | G16: =(SUMIFS('Détail du PI'!$N$326:$N$345,'Détail du PI'!$B$326:$B$345,G$14)) / 1000 -> 0 | H16: =(SUMIFS('Détail du PI'!$N$326:$N$345,'Détail du PI'!$B$326:$B$345,H$14)) / 1000 -> 0 | I16: =(SUMIFS('Détail du PI'!$N$326:$N$345,'Détail du PI'!$B$326:$B$345,I$14)) / 1000 -> 0 | J16: =SUM(E16:I16) -> 0 | L16: =('Détail du PI'!$P$347) / 1000 -> 0 | M16: =IFERROR(J16/$J$25, 0) -> 0
B17: Terrain | E17: =(SUMIFS('Détail du PI'!$N$20:$N$54,'Détail du PI'!$B$20:$B$54,E$14)) / 1000 -> 0 | F17: =(SUMIFS('Détail du PI'!$N$20:$N$54,'Détail du PI'!$B$20:$B$54,F$14)) / 1000 -> 0 | G17: =(SUMIFS('Détail du PI'!$N$20:$N$54,'Détail du PI'!$B$20:$B$54,G$14)) / 1000 -> 0 | H17: =(SUMIFS('Détail du PI'!$N$20:$N$54,'Détail du PI'!$B$20:$B$54,H$14)) / 1000 -> 0 | I17: =(SUMIFS('Détail du PI'!$N$20:$N$54,'Détail du PI'!$B$20:$B$54,I$14)) / 1000 -> 0 | J17: =SUM(E17:I17) -> 0 | L17: =('Détail du PI'!$P$56) / 1000 -> 0 | M17: =IFERROR(J17/$J$25, 0) -> 0
B18: Constructions | E18: =(SUMIFS('Détail du PI'!$N$60:$N$109,'Détail du PI'!$B$60:$B$109,E$14)) / 1000 -> 0 | F18: =(SUMIFS('Détail du PI'!$N$60:$N$109,'Détail du PI'!$B$60:$B$109,F$14)) / 1000 -> 0 | G18: =(SUMIFS('Détail du PI'!$N$60:$N$109,'Détail du PI'!$B$60:$B$109,G$14)) / 1000 -> 0 | H18: =(SUMIFS('Détail du PI'!$N$60:$N$109,'Détail du PI'!$B$60:$B$109,H$14)) / 1000 -> 0 | I18: =(SUMIFS('Détail du PI'!$N$60:$N$109,'Détail du PI'!$B$60:$B$109,I$14)) / 1000 -> 0 | J18: =SUM(E18:I18) -> 0 | L18: =('Détail du PI'!$P$111) / 1000 -> 0 | M18: =IFERROR(J18/$J$25, 0) -> 0
B19: Aménagement et agencement | E19: =(SUMIFS('Détail du PI'!$N$115:$N$164,'Détail du PI'!$B$115:$B$164,E$14)) / 1000 -> 0 | F19: =(SUMIFS('Détail du PI'!$N$115:$N$164,'Détail du PI'!$B$115:$B$164,F$14)) / 1000 -> 0 | G19: =(SUMIFS('Détail du PI'!$N$115:$N$164,'Détail du PI'!$B$115:$B$164,G$14)) / 1000 -> 0 | H19: =(SUMIFS('Détail du PI'!$N$115:$N$164,'Détail du PI'!$B$115:$B$164,H$14)) / 1000 -> 0 | I19: =(SUMIFS('Détail du PI'!$N$115:$N$164,'Détail du PI'!$B$115:$B$164,I$14)) / 1000 -> 0 | J19: =SUM(E19:I19) -> 0 | L19: =('Détail du PI'!$P$166) / 1000 -> 0 | M19: =IFERROR(J19/$J$25, 0) -> 0
B20: Matériel d'équipement** | E20: =(SUMIFS('Détail du PI'!$N$170:$N$320,'Détail du PI'!$B$170:$B$320,E$14)) / 1000 -> 0 | F20: =(SUMIFS('Détail du PI'!$N$170:$N$320,'Détail du PI'!$B$170:$B$320,F$14)) / 1000 -> 0 | G20: =(SUMIFS('Détail du PI'!$N$170:$N$320,'Détail du PI'!$B$170:$B$320,G$14)) / 1000 -> 0 | H20: =(SUMIFS('Détail du PI'!$N$170:$N$320,'Détail du PI'!$B$170:$B$320,H$14)) / 1000 -> 0 | I20: =(SUMIFS('Détail du PI'!$N$170:$N$320,'Détail du PI'!$B$170:$B$320,I$14)) / 1000 -> 0 | J20: =SUM(E20:I20) -> 0 | L20: =('Détail du PI'!$P$322) / 1000 -> 0 | M20: =IFERROR(J20/$J$25, 0) -> 0
B21: Divers et imprévus | E21: =(SUMIFS('Détail du PI'!$N$351:$N$355,'Détail du PI'!$B$351:$B$355,E$14)) / 1000 -> 0 | F21: =(SUMIFS('Détail du PI'!$N$351:$N$355,'Détail du PI'!$B$351:$B$355,F$14)) / 1000 -> 0 | G21: =(SUMIFS('Détail du PI'!$N$351:$N$355,'Détail du PI'!$B$351:$B$355,G$14)) / 1000 -> 0 | H21: =(SUMIFS('Détail du PI'!$N$351:$N$355,'Détail du PI'!$B$351:$B$355,H$14)) / 1000 -> 0 | I21: =(SUMIFS('Détail du PI'!$N$351:$N$355,'Détail du PI'!$B$351:$B$355,I$14)) / 1000 -> 0 | J21: =SUM(E21:I21) -> 0 | L21: =('Détail du PI'!$P$357) / 1000 -> 0 | M21: =IFERROR(J21/$J$25, 0) -> 0
B23: Investissement total | E23: =SUM(E16:E21) -> 0 | F23: =SUM(F16:F21) -> 0 | G23: =SUM(G16:G21) -> 0 | H23: =SUM(H16:H21) -> 0 | I23: =SUM(I16:I21) -> 0 | J23: =SUM(J16:J21) -> 0 | L23: =SUM(L16:L21) -> 0
B25: > Total global | E25: =E23 -> 0 | F25: =F23 -> 0 | G25: =G23 -> 0 | H25: =H23 -> 0 | I25: =I23 -> 0 | J25: =J23 -> 0 | L25: =L23 -> 0
B26: * y compris frais d'approche |** du HT
B27: ** y compris les frais d'approche
B29: FINANCEMENT DU PI (en KMAD) | E29: Fonds propres* | F29: CMT | G29: Financement participatif | H29: Crédit fournisseur | I29: Leasing
B31: Frais préliminaires | L31: =L16-SUM(E31:I31) -> 0
B32: Terrain | L32: =L17-SUM(E32:I32) -> 0
B33: Constructions | L33: =L18-SUM(E33:I33) -> 0
B34: Aménagement et agencement | L34: =L19-SUM(E34:I34) -> 0
B35: Frais d'approche
B36: Matériel d'équipement & de manutention | L36: =L20-SUM(E35:I36) -> 0
B37: Divers et imprévus | L37: =L21-SUM(E37:I37) -> 0
L38: =L23-SUM(E38:I38) -> 0
B39: Investissement total | E39: =SUM(E31:E37) -> 0 | F39: =SUM(F31:F37) -> 0 | G39: =SUM(G31:G37) -> 0 | H39: =SUM(H31:H37) -> 0 | I39: =SUM(I31:I37) -> 0
B41: %* | E41: =IFERROR(E39/$L$25, 0) -> 0 | F41: =IFERROR(F39/$L$25, 0) -> 0 | G41: =IFERROR(G39/$L$25, 0) -> 0 | H41: =IFERROR(H39/$L$25, 0) -> 0 | I41: =IFERROR(I39/$L$25, 0) -> 0
B42: * incluant les comptes courants d'associés
B43: ** en % du total du plan de financement
E44: =SUM(E39,-'Mode de financement'!G16) -> 0 | F44: =SUM(F39,-'Mode de financement'!H16) -> 0 | G44: =SUM(G39,-'Mode de financement'!I16) -> 0 | H44: =SUM(H39,-'Mode de financement'!J16) -> 0 | I44: =SUM(I39,-'Mode de financement'!K16) -> 0

Sheet Mode de financement
A1: =Couverture!G20 -> MaSociété
A2: =IFERROR(MID(CELL("filename",A2),FIND("]",CELL("filename",A2))+1,255),"< - >") -> Mode de financement
A3: =+IF(AND(SUM(G16:L16)=E16,L26=L16),"Cohérent","Non cohérent") -> Cohérent
B5: ANPMExpert: > Il est necessaire de renseigner le déblocage de la prime sur la période prévisionnelle dépendamment de l'état de réalisation du projet d'investissement (cf. Règlement d'appel à projet).
B11: FINANCEMENT DU PROGRAMME D'INVESTISSEMENT
G13: Mode de financement | N13: % Contribution
B14: FINANCEMENT (en KMAD) | G14: Fonds propres* | H14: CMT | I14: Financement participatif | J14: Crédit fournisseurs | K14: Leasing | L14: Prime ISTITMAR | N14: Fonds propres* | O14: CMT | P14: Financement participatif | Q14: =J14 -> Crédit fournisseurs | R14: Leasing | S14: Prime ISTITMAR
B16: Investissement total | E16: ='Synthèse du PI'!L23 -> 0 | G16: 0 | H16: 0 | I16: 0 | J16: 0 | K16: 0 | L16: =IF(Synthèse!D12="Hébergement touristique adossé à l'animation",MIN(10000*30%,30%*E16),MIN(10000*35%,35%*E16)) -> 0 | N16: =IFERROR(G16/$E$16, 0) -> 0 | O16: =IFERROR(H16/$E$16, 0) -> 0 | P16: =IFERROR(I16/$E$16, 0) -> 0 | Q16: =IFERROR(J16/$E$16, 0) -> 0 | R16: =IFERROR(K16/$E$16, 0) -> 0 | S16: =IFERROR(L16/$E$16, 0) -> 0
B18: * incluant les comptes courants d'associés
G20: =SUM(G16-'Synthèse du PI'!E39) -> 0 | H20: =SUM(H16-'Synthèse du PI'!F39) -> 0 | J20: =SUM(J16-'Synthèse du PI'!H39) -> 0 | K20: =SUM(K16-'Synthèse du PI'!I39) -> 0
B24: DEBLOCAGE DE LA PRIME (en KMAD) | G24: =_xlfn.NUMBERVALUE(YPL1) -> 2026 | H24: =G24+1 -> 2027 | I24: =H24+1 -> 2028 | J24: =+I24+1 -> 2029 | K24: =J24+1 -> 2030 | L24: Total
B26: Prime ISTITMAR | G26: 0 | H26: 0 | I26: 0 | J26: 0 | K26: 0 | L26: =SUM(G26:K26) -> 0 | N26: =IF((L26-L16)=0,""," > Merci de vérifier le planning de déblocage")

Sheet Bilan
A1: =Couverture!G20 -> MaSociété
A2: =IFERROR(MID(CELL("filename",A2),FIND("]",CELL("filename",A2))+1,255),"< - >") -> Bilan
A3: =IF(AND(ABS(E85)<50,ABS(F85)<50,ABS(H85)<50,ABS(I85)<50,ABS(J85)<50,ABS(K85)<50,ABS(L85)<50,ABS(M85)<50,ABS(D85)<50),"Equilibré","Déséquilibré") -> Equilibré
B5: ANPMExpert: > Les chiffres doivent être présentés en KMAD (milliers de dirham marocain). > Merci de ne pas omettre la constatation de la subvention d'investissement (à amortir).
D11: ="Période historique"&IF(Synthèse!D18="Création"," - Non applicable","") -> Période historique - Non applicable | H11: Période prévisionnelle
B12: Bilan - Actif (en KMAD) | D12: =_xlfn.NUMBERVALUE(YPL1)-5 -> 2021 | E12: =D12+3 -> 2024 | F12: =E12+1 -> 2025 | H12: =_xlfn.NUMBERVALUE(YPL1) -> 2026 | I12: =H12+1 -> 2027 | J12: =I12+1 -> 2028 | K12: =J12+1 -> 2029 | L12: =K12+1 -> 2030 | M12: =L12+1 -> 2031
D13: =IF(Synthèse!$D$18="Création",1,0) -> 1 | E13: =D13 -> 1 | F13: =D13 -> 1
B14: Immobilisation en non valeur, net | D14: 0 | E14: 0 | F14: 0 | H14: 0 | I14: 0 | J14: 0 | K14: 0 | L14: 0 | M14: 0
B15: Immobilisations incorporelles, net | D15: 0 | E15: 0 | F15: 0 | H15: 0 | I15: 0 | J15: 0 | K15: 0 | L15: 0 | M15: 0
B16: Terrains | D16: 0 | E16: 0 | F16: 0 | H16: 0 | I16: 0 | J16: 0 | K16: 0 | L16: 0 | M16: 0
B17: Constructions, net | D17: 0 | E17: 0 | F17: 0 | H17: 0 | I17: 0 | J17: 0 | K17: 0 | L17: 0 | M17: 0
B18: Instal. tech., matériel et outillages, net | D18: 0 | E18: 0 | F18: 0 | H18: 0 | I18: 0 | J18: 0 | K18: 0 | L18: 0 | M18: 0
B19: Matériel de transport, net | D19: 0 | E19: 0 | F19: 0 | H19: 0 | I19: 0 | J19: 0 | K19: 0 | L19: 0 | M19: 0
B20: Mobilier, mat. bureau et aménag., net | D20: 0 | E20: 0 | F20: 0 | H20: 0 | I20: 0 | J20: 0 | K20: 0 | L20: 0 | M20: 0
B21: Autres immo. corporelles, net | D21: 0 | E21: 0 | F21: 0 | H21: 0 | I21: 0 | J21: 0 | K21: 0 | L21: 0 | M21: 0
B22: Immo. corporelles en cours | D22: 0 | E22: 0 | F22: 0 | H22: 0 | I22: 0 | J22: 0 | K22: 0 | L22: 0 | M22: 0
B23: Immobilisations corporelles, net | D23: =SUM(D16:D22) -> 0 | E23: =SUM(E16:E22) -> 0 | F23: =SUM(F16:F22) -> 0 | H23: =SUM(H16:H22) -> 0 | I23: =SUM(I16:I22) -> 0 | J23: =SUM(J16:J22) -> 0 | K23: =SUM(K16:K22) -> 0 | L23: =SUM(L16:L22) -> 0 | M23: =SUM(M16:M22) -> 0
B24: Immobilisations financières, net | D24: 0 | E24: 0 | F24: 0 | H24: 0 | I24: 0 | J24: 0 | K24: 0 | L24: 0 | M24: 0
B25: Ecarts de conversion - Actif | D25: 0 | E25: 0 | F25: 0 | H25: 0 | I25: 0 | J25: 0 | K25: 0 | L25: 0 | M25: 0
B27: Actif immobilisé | D27: =SUM(D14,D15,D23,D24,D25) -> 0 | E27: =SUM(E14,E15,E23,E24,E25) -> 0 | F27: =SUM(F14,F15,F23,F24,F25) -> 0 | H27: =SUM(H14,H15,H23,H24,H25) -> 0 | I27: =SUM(I14,I15,I23,I24,I25) -> 0 | J27: =SUM(J14,J15,J23,J24,J25) -> 0 | K27: =SUM(K14,K15,K23,K24,K25) -> 0 | L27: =SUM(L14,L15,L23,L24,L25) -> 0 | M27: =SUM(M14,M15,M23,M24,M25) -> 0
B29: Marchandises, net | D29: 0 | E29: 0 | F29: 0 | H29: 0 | I29: 0 | J29: 0 | K29: 0 | L29: 0 | M29: 0
B30: Matières. et fournit. consommables, net | D30: 0 | E30: 0 | F30: 0 | H30: 0 | I30: 0 | J30: 0 | K30: 0 | L30: 0 | M30: 0
B31: Produits en cours | D31: 0 | E31: 0 | F31: 0 | H31: 0 | I31: 0 | J31: 0 | K31: 0 | L31: 0 | M31: 0
B32: Produits interméd. et prod. résiduels | D32: 0 | E32: 0 | F32: 0 | H32: 0 | I32: 0 | J32: 0 | K32: 0 | L32: 0 | M32: 0
B33: Produits finis, net | D33: 0 | E33: 0 | F33: 0 | H33: 0 | I33: 0 | J33: 0 | K33: 0 | L33: 0 | M33: 0
B34: Stocks, net | D34: =SUM(D29:D33) -> 0 | E34: =SUM(E29:E33) -> 0 | F34: =SUM(F29:F33) -> 0 | H34: =SUM(H29:H33) -> 0 | I34: =SUM(I29:I33) -> 0 | J34: =SUM(J29:J33) -> 0 | K34: =SUM(K29:K33) -> 0 | L34: =SUM(L29:L33) -> 0 | M34: =SUM(M29:M33) -> 0
B35: Fournis. débit. - avances et acomptes | D35: 0 | E35: 0 | F35: 0 | H35: 0 | I35: 0 | J35: 0 | K35: 0 | L35: 0 | M35: 0
B36: Clients et comptes rattachés, net | D36: 0 | E36: 0 | F36: 0 | H36: 0 | I36: 0 | J36: 0 | K36: 0 | L36: 0 | M36: 0
B37: Comptes d'associés, net | D37: 0 | E37: 0 | F37: 0 | H37: 0 | I37: 0 | J37: 0 | K37: 0 | L37: 0 | M37: 0
B38: Autres créances, net | D38: 0 | E38: 0 | F38: 0 | H38: 0 | I38: 0 | J38: 0 | K38: 0 | L38: 0 | M38: 0
B39: Créances, net | D39: =SUM(D35:D38) -> 0 | E39: =SUM(E35:E38) -> 0 | F39: =SUM(F35:F38) -> 0 | H39: =SUM(H35:H38) -> 0 | I39: =SUM(I35:I38) -> 0 | J39: =SUM(J35:J38) -> 0 | K39: =SUM(K35:K38) -> 0 | L39: =SUM(L35:L38) -> 0 | M39: =SUM(M35:M38) -> 0
B40: Titres et autres valeurs de placement | D40: 0 | E40: 0 | F40: 0 | H40: 0 | I40: 0 | J40: 0 | K40: 0 | L40: 0 | M40: 0
B41: Ecarts de conversion - Actif | D41: 0 | E41: 0 | F41: 0 | H41: 0 | I41: 0 | J41: 0 | K41: 0 | L41: 0 | M41: 0
B43: Actif circulant | D43: =SUM(D34,D39,D40:D41) -> 0 | E43: =SUM(E34,E39,E40:E41) -> 0 | F43: =SUM(F34,F39,F40:F41) -> 0 | H43: =SUM(H34,H39,H40:H41) -> 0 | I43: =SUM(I34,I39,I40:I41) -> 0 | J43: =SUM(J34,J39,J40:J41) -> 0 | K43: =SUM(K34,K39,K40:K41) -> 0 | L43: =SUM(L34,L39,L40:L41) -> 0 | M43: =SUM(M34,M39,M40:M41) -> 0
B45: Trésorerie - Actif | D45: 0 | E45: 0 | F45: 0 | H45: 0 | I45: 0 | J45: 0 | K45: 0 | L45: 0 | M45: 0
B47: Total Actif | D47: =SUM(D27,D43,D45) -> 0 | E47: =SUM(E27,E43,E45) -> 0 | F47: =SUM(F27,F43,F45) -> 0 | H47: =SUM(H27,H43,H45) -> 0 | I47: =SUM(I27,I43,I45) -> 0 | J47: =SUM(J27,J43,J45) -> 0 | K47: =SUM(K27,K43,K45) -> 0 | L47: =SUM(L27,L43,L45) -> 0 | M47: =SUM(M27,M43,M45) -> 0
B49: Bilan - Passif (en KMAD) | D49: =_xlfn.NUMBERVALUE(YPL1)-3 -> 2023 | E49: =D49+1 -> 2024 | F49: =E49+1 -> 2025 | H49: =_xlfn.NUMBERVALUE(YPL1) -> 2026 | I49: =H49+1 -> 2027 | J49: =I49+1 -> 2028 | K49: =J49+1 -> 2029 | L49: =K49+1 -> 2030 | M49: =L49+1 -> 2031
D50: =D13 -> 1 | E50: =E13 -> 1 | F50: =F13 -> 1
B51: Capital | D51: 0 | E51: 0 | F51: 0 | H51: 0 | I51: 0 | J51: 0 | K51: 0 | L51: 0 | M51: 0
B52: Primes d'émission, de fusion et d'apport | D52: 0 | E52: 0 | F52: 0 | H52: 0 | I52: 0 | J52: 0 | K52: 0 | L52: 0 | M52: 0
...

Sheet CPC
A1: =Couverture!G20 -> MaSociété
A2: =IFERROR(MID(CELL("filename",A2),FIND("]",CELL("filename",A2))+1,255),"< - >") -> CPC
B5: ANPMExpert: > Les chiffres doivent être présentés en KMAD (milliers de dirham marocain).
D11: ="Période historique"&IF(Synthèse!D18="Création"," - Non applicable","") -> Période historique - Non applicable | H11: Période prévisionnelle
B12: CPC (en KMAD) | D12: =_xlfn.NUMBERVALUE(YPL1)-3 -> 2023 | E12: =D12+1 -> 2024 | F12: =E12+1 -> 2025 | H12: =_xlfn.NUMBERVALUE(YPL1) -> 2026 | I12: =H12+1 -> 2027 | J12: =I12+1 -> 2028 | K12: =J12+1 -> 2029 | L12: =K12+1 -> 2030 | M12: =L12+1 -> 2031
D13: =Bilan!D50 -> 1 | E13: =Bilan!E50 -> 1 | F13: =Bilan!F50 -> 1
B14: Ventes de marchandises - en l'état | D14: 0 | E14: 0 | F14: 0 | H14: 0 | I14: 0 | J14: 0 | K14: 0 | L14: 0 | M14: 0
B15: Hébergement (Chambres/Unités) | H15: 0 | I15: 0 | J15: 0 | K15: 0 | L15: 0 | M15: 0
B16: Restauration (Food & Beverage) | H16: 0 | I16: 0 | J16: 0 | K16: 0 | L16: 0 | M16: 0
B17: Animation | H17: 0 | I17: 0 | J17: 0 | K17: 0 | L17: 0 | M17: 0
B18: Autres | H18: 0 | I18: 0 | J18: 0 | K18: 0 | L18: 0 | M18: 0
B19: Ventes de biens et services produits | D19: 0 | E19: 0 | F19: 0 | H19: 0 | I19: 0 | J19: 0 | K19: 0 | L19: 0 | M19: 0
B20: Chiffre d'affaires (CA) global | D20: =SUM(D14:D19) -> 0 | E20: =SUM(E14:E19) -> 0 | F20: =SUM(F14:F19) -> 0 | H20: =SUM(H15:H18) -> 0 | I20: =SUM(I15:I18) -> 0 | J20: =SUM(J15:J18) -> 0 | K20: =SUM(K15:K18) -> 0 | L20: =SUM(L15:L18) -> 0 | M20: =SUM(M15:M18) -> 0
B21: Variation de stocks de produits | D21: 0 | E21: 0 | F21: 0 | H21: 0 | I21: 0 | J21: 0 | K21: 0 | L21: 0 | M21: 0
B22: Autres produits d'exploitation | D22: 0 | E22: 0 | F22: 0 | H22: 0 | I22: 0 | J22: 0 | K22: 0 | L22: 0 | M22: 0
B24: Produits d'exploitation | D24: =SUM(D20:D22) -> 0 | E24: =SUM(E20:E22) -> 0 | F24: =SUM(F20:F22) -> 0 | H24: =SUM(H20:H22) -> 0 | I24: =SUM(I20:I22) -> 0 | J24: =SUM(J20:J22) -> 0 | K24: =SUM(K20:K22) -> 0 | L24: =SUM(L20:L22) -> 0 | M24: =SUM(M20:M22) -> 0
B27: Hébergement (Chambres/Unités) | H27: 0 | I27: 0 | J27: 0 | K27: 0 | L27: 0 | M27: 0
B28: Restauration (Food & Beverage) | H28: 0 | I28: 0 | J28: 0 | K28: 0 | L28: 0 | M28: 0
B29: Animation | H29: 0 | I29: 0 | J29: 0 | K29: 0 | L29: 0 | M29: 0
B30: Autres | H30: 0 | I30: 0 | J30: 0 | K30: 0 | L30: 0 | M30: 0
B31: Achats* | D31: 0 | E31: 0 | F31: 0 | H31: =SUM(H27:H30) -> 0 | I31: =SUM(I27:I30) -> 0 | J31: =SUM(J27:J30) -> 0 | K31: =SUM(K27:K30) -> 0 | L31: =SUM(L27:L30) -> 0 | M31: =SUM(M27:M30) -> 0
B32: Loyers et Charges locatives | H32: 0 | I32: 0 | J32: 0 | K32: 0 | L32: 0 | M32: 0
B33: Redevances de crédit-bail | D33: 0 | E33: 0 | F33: 0 | H33: 0 | I33: 0 | J33: 0 | K33: 0 | L33: 0 | M33: 0
B34: Autres charges externes | D34: 0 | E34: 0 | F34: 0 | H34: 0 | I34: 0 | J34: 0 | K34: 0 | L34: 0 | M34: 0
B35: Autres charges externes | D35: =SUM(D32:D34) -> 0 | E35: =SUM(E32:E34) -> 0 | F35: =SUM(F32:F34) -> 0 | H35: =SUM(H32:H34) -> 0 | I35: =SUM(I32:I34) -> 0 | J35: =SUM(J32:J34) -> 0 | K35: =SUM(K32:K34) -> 0 | L35: =SUM(L32:L34) -> 0 | M35: =SUM(M32:M34) -> 0
B36: Impôts et taxes | D36: 0 | E36: 0 | F36: 0 | H36: 0 | I36: 0 | J36: 0 | K36: 0 | L36: 0 | M36: 0
B37: Hébergement (Chambres/Unités) | H37: 0 | I37: 0 | J37: 0 | K37: 0 | L37: 0 | M37: 0
B38: Restauration (Food & Beverage) | H38: 0 | I38: 0 | J38: 0 | K38: 0 | L38: 0 | M38: 0
B39: Animation | H39: 0 | I39: 0 | J39: 0 | K39: 0 | L39: 0 | M39: 0
B40: Admin. et Gestion | H40: 0 | I40: 0 | J40: 0 | K40: 0 | L40: 0 | M40: 0
B41: Autres | H41: 0 | I41: 0 | J41: 0 | K41: 0 | L41: 0 | M41: 0
B42: Charges de personnel | D42: 0 | E42: 0 | F42: 0 | H42: =SUM(H37:H41) -> 0 | I42: =SUM(I37:I41) -> 0 | J42: =SUM(J37:J41) -> 0 | K42: =SUM(K37:K41) -> 0 | L42: =SUM(L37:L41) -> 0 | M42: =SUM(M37:M41) -> 0
B43: Autres charges d'exploitation | D43: 0 | E43: 0 | F43: 0 | H43: 0 | I43: 0 | J43: 0 | K43: 0 | L43: 0 | M43: 0
B44: Dotations d'exploitation | D44: 0 | E44: 0 | F44: 0 | H44: 0 | I44: 0 | J44: 0 | K44: 0 | L44: 0 | M44: 0
B46: Charges d'exploitation | D46: =SUM(D26:D31,D35:D44) -> 0 | E46: =SUM(E26:E31,E35:E44) -> 0 | F46: =SUM(F26:F31,F35:F44) -> 0 | H46: =SUM(H31,H35,H36,H42,H43,H44) -> 0 | I46: =SUM(I31,I35,I36,I42,I43,I44) -> 0 | J46: =SUM(J31,J35,J36,J42,J43,J44) -> 0 | K46: =SUM(K31,K35,K36,K42,K43,K44) -> 0 | L46: =SUM(L31,L35,L36,L42,L43,L44) -> 0 | M46: =SUM(M31,M35,M36,M42,M43,M44) -> 0
B48: Résultat d'exploitation | D48: =SUM(D24,-D46) -> 0 | E48: =SUM(E24,-E46) -> 0 | F48: =SUM(F24,-F46) -> 0 | H48: =SUM(H24,-H46) -> 0 | I48: =SUM(I24,-I46) -> 0 | J48: =SUM(J24,-J46) -> 0 | K48: =SUM(K24,-K46) -> 0 | L48: =SUM(L24,-L46) -> 0 | M48: =SUM(M24,-M46) -> 0
B50: Produits financiers | D50: 0 | E50: 0 | F50: 0 | H50: 0 | I50: 0 | J50: 0 | K50: 0 | L50: 0 | M50: 0
B51: Charges financières | D51: 0 | E51: 0 | F51: 0 | H51: 0 | I51: 0 | J51: 0 | K51: 0 | L51: 0 | M51: 0
B52: Résultat financier | D52: =SUM(D50,-D51) -> 0 | E52: =SUM(E50,-E51) -> 0 | F52: =SUM(F50,-F51) -> 0 | H52: =SUM(H50,-H51) -> 0 | I52: =SUM(I50,-I51) -> 0 | J52: =SUM(J50,-J51) -> 0 | K52: =SUM(K50,-K51) -> 0 | L52: =SUM(L50,-L51) -> 0 | M52: =SUM(M50,-M51) -> 0
B54: Résultat courant | D54: =SUM(D48,D52) -> 0 | E54: =SUM(E48,E52) -> 0 | F54: =SUM(F48,F52) -> 0 | H54: =SUM(H48,H52) -> 0 | I54: =SUM(I48,I52) -> 0 | J54: =SUM(J48,J52) -> 0 | K54: =SUM(K48,K52) -> 0 | L54: =SUM(L48,L52) -> 0 | M54: =SUM(M48,M52) -> 0
...

Sheet 1 (A ne pas supprimer)
C7: Liste des banques
C8: AL AKHDAR BANK
C9: Arab Bank Maroc
C10: Attijariwafa Bank
C11: Banque centrale populaire
C12: Banque marocaine pour le commerce et l'industrie
C13: BMCE Bank of Africa
C14: BMCI Leasing
C15: CAM Leasing
C16: CFG BANK
C17: CIH Bank
C18: CITI Bank
... C26: Autre
C28: Devises | D28: Taux
C29: MAD | D29: 1
C30: EUR | D30: 11
C31: USD | D31: 10
C32: CHF (Franc suisse) | D32: 11
C33: GBP (Livre sterling) | D33: 12.5
C34: Autre | D34: 0
C38: Taux g | D38: 0.025
C39: Taux CP | D39: 0.12
C40: Taux dette | D40: 0.12
F45: 2025(*) | G45: 2026(*) | H45: 2027(*) | I45: 2028(*) | J45: 2029(*) | K45: 2030(*)
C46: Bénéfice net fiscal ≤ à 300 000 DH : | D46: 0 | E46: 300000 | F46: 0.175 | G46: 0.2 | H46: 0.2 | I46: 0.2 | J46: 0.2 | K46: 0.2
C47: 300 000 DH < Bénéfice net fiscal < 1MDH : | D47: 300000 | E47: 1000000 | F47: 0.2 | G47: 0.2 | H47: 0.2 | I47: 0.2 | J47: 0.2 | K47: 0.2
C48: 1M DH < Bénéfice net fiscal < 100MDH : | D48: 1000000 | E48: 100000000 | F48: 0.2275 | G48: 0.2 | H48: 0.2 | I48: 0.2 | J48: 0.2 | K48: 0.2
C49: Bénéfice net fiscal ≥ 100 MDH | D49: 100000000 | F49: 0.34 | G49: 0.35 | H49: 0.35 | I49: 0.35 | J49: 0.35 | K49: 0.35
C54: =_xlfn.NUMBERVALUE(YPL1) -> 2026
C55: =C54+1 -> 2027
C56: =C55+1 -> 2028
C57: =C56+1 -> 2029
C58: =+C57+1 -> 2030

Sheet  2 ((A ne pas supprimer)
A1: =Couverture!G20 -> MaSociété
A2: =IFERROR(MID(CELL("filename",A2),FIND("]",CELL("filename",A2))+1,255),"< - >") -> 2 ((A ne pas supprimer)
D5: ANPMExpert: > les chiffres doivent être présentés en KMAD (milliers de dirham marocain) > les chiffres du CPC projet ne peuvent en aucun cas dépasser les chiffres du CPC global.
H11: Période prévisionnelle
B12: CPC projet (en KMAD) | H12: =_xlfn.NUMBERVALUE(YPL1) -> 2026 | I12: =H12+1 -> 2027 | J12: =I12+1 -> 2028 | K12: =J12+1 -> 2029 | L12: =K12+1 -> 2030 | M12: =L12+1 -> 2031
B14: Ventes de marchandises - en l'état | H14: =CPC!H14 -> 0 | I14: =CPC!I14 -> 0 | J14: =CPC!J14 -> 0 | K14: =CPC!K14 -> 0 | L14: =CPC!L14 -> 0 | M14: =CPC!M14 -> 0
B15: Ventes des biens et services produits | H15: =SUM(CPC!H15:H18) -> 0 | I15: =SUM(CPC!I15:I18) -> 0 | J15: =SUM(CPC!J15:J18) -> 0 | K15: =SUM(CPC!K15:K18) -> 0 | L15: =SUM(CPC!L15:L18) -> 0 | M15: =SUM(CPC!M15:M18) -> 0
B16: Chiffre d'affaires du projet | H16: =CPC!H20 -> 0 | I16: =CPC!I20 -> 0 | J16: =CPC!J20 -> 0 | K16: =CPC!K20 -> 0 | L16: =CPC!L20 -> 0 | M16: =CPC!M20 -> 0
B17: Variation de stocks de produits | H17: =CPC!H21 -> 0 | I17: =CPC!I21 -> 0 | J17: =CPC!J21 -> 0 | K17: =CPC!K21 -> 0 | L17: =CPC!L21 -> 0 | M17: =CPC!M21 -> 0
B18: Autres produits d'exploitation | H18: =CPC!H22 -> 0 | I18: =CPC!I22 -> 0 | J18: =CPC!J22 -> 0 | K18: =CPC!K22 -> 0 | L18: =CPC!L22 -> 0 | M18: =CPC!M22 -> 0
B20: Produits d'exploitation | H20: =SUM(H16:H18) -> 0 | I20: =SUM(I16:I18) -> 0 | J20: =SUM(J16:J18) -> 0 | K20: =SUM(K16:K18) -> 0 | L20: =SUM(L16:L18) -> 0 | M20: =SUM(M16:M18) -> 0
B22: Achats revendus de marchandises
B23: Achats consommés de matières et fournitures | H23: =CPC!H31 -> 0 | I23: =CPC!I31 -> 0 | J23: =CPC!J31 -> 0 | K23: =CPC!K31 -> 0 | L23: =CPC!L31 -> 0 | M23: =CPC!M31 -> 0
B24: Redevances de crédit-bail | H24: =CPC!H33 -> 0 | I24: =CPC!I33 -> 0 | J24: =CPC!J33 -> 0 | K24: =CPC!K33 -> 0 | L24: =CPC!L33 -> 0 | M24: =CPC!M33 -> 0
B25: Autres charges externes | H25: =CPC!H34 -> 0 | I25: =CPC!I34 -> 0 | J25: =CPC!J34 -> 0 | K25: =CPC!K34 -> 0 | L25: =CPC!L34 -> 0 | M25: =CPC!M34 -> 0
B26: Autres charges externes | H26: =CPC!H35 -> 0 | I26: =CPC!I35 -> 0 | J26: =CPC!J35 -> 0 | K26: =CPC!K35 -> 0 | L26: =CPC!L35 -> 0 | M26: =CPC!M35 -> 0
B27: Impôts et taxes | H27: =CPC!H36 -> 0 | I27: =CPC!I36 -> 0 | J27: =CPC!J36 -> 0 | K27: =CPC!K36 -> 0 | L27: =CPC!L36 -> 0 | M27: =CPC!M36 -> 0
B28: Charges de personnel | H28: =CPC!H42 -> 0 | I28: =CPC!I42 -> 0 | J28: =CPC!J42 -> 0 | K28: =CPC!K42 -> 0 | L28: =CPC!L42 -> 0 | M28: =CPC!M42 -> 0
B29: Autres charges d'exploitation | H29: =CPC!H43 -> 0 | I29: =CPC!I43 -> 0 | J29: =CPC!J43 -> 0 | K29: =CPC!K43 -> 0 | L29: =CPC!L43 -> 0 | M29: =CPC!M43 -> 0
B30: Dotations d'exploitation | H30: =CPC!H44 -> 0 | I30: =CPC!I44 -> 0 | J30: =CPC!J44 -> 0 | K30: =CPC!K44 -> 0 | L30: =CPC!L44 -> 0 | M30: =CPC!M44 -> 0
B32: Charges d'exploitation | H32: =SUM(H22:H23,H26:H30) -> 0 | I32: =SUM(I22:I23,I26:I30) -> 0 | J32: =SUM(J22:J23,J26:J30) -> 0 | K32: =SUM(K22:K23,K26:K30) -> 0 | L32: =SUM(L22:L23,L26:L30) -> 0 | M32: =SUM(M22:M23,M26:M30) -> 0
B34: Résultat d'exploitation | H34: =SUM(H20,-H32) -> 0 | I34: =SUM(I20,-I32) -> 0 | J34: =SUM(J20,-J32) -> 0 | K34: =SUM(K20,-K32) -> 0 | L34: =SUM(L20,-L32) -> 0 | M34: =SUM(M20,-M32) -> 0
B36: Produits financiers | H36: =CPC!H50 -> 0 | I36: =CPC!I50 -> 0 | J36: =CPC!J50 -> 0 | K36: =CPC!K50 -> 0 | L36: =CPC!L50 -> 0 | M36: =CPC!M50 -> 0
B37: Charges financières | H37: =CPC!H51 -> 0 | I37: =CPC!I51 -> 0 | J37: =CPC!J51 -> 0 | K37: =CPC!K51 -> 0 | L37: =CPC!L51 -> 0 | M37: =CPC!M51 -> 0
B38: Résultat financier | H38: =SUM(H36,-H37) -> 0 | I38: =SUM(I36,-I37) -> 0 | J38: =SUM(J36,-J37) -> 0 | K38: =SUM(K36,-K37) -> 0 | L38: =SUM(L36,-L37) -> 0 | M38: =SUM(M36,-M37) -> 0
B40: Résultat courant | H40: =SUM(H34,H38) -> 0 | I40: =SUM(I34,I38) -> 0 | J40: =SUM(J34,J38) -> 0 | K40: =SUM(K34,K38) -> 0 | L40: =SUM(L34,L38) -> 0 | M40: =SUM(M34,M38) -> 0
B42: Produits non courants | H42: =CPC!H56 -> 0 | I42: =CPC!I56 -> 0 | J42: =CPC!J56 -> 0 | K42: =CPC!K56 -> 0 | L42: =CPC!L56 -> 0 | M42: =CPC!M56 -> 0
B43: Charges non courantes | H43: =CPC!H57 -> 0 | I43: =CPC!I57 -> 0 | J43: =CPC!J57 -> 0 | K43: =CPC!K57 -> 0 | L43: =CPC!L57 -> 0 | M43: =CPC!M57 -> 0
B45: Résultat non courant | H45: =SUM(H42,-H43) -> 0 | I45: =SUM(I42,-I43) -> 0 | J45: =SUM(J42,-J43) -> 0 | K45: =SUM(K42,-K43) -> 0 | L45: =SUM(L42,-L43) -> 0 | M45: =SUM(M42,-M43) -> 0
B47: Résultat avant Impôts | H47: =SUM(H40,H45) -> 0 | I47: =SUM(I40,I45) -> 0 | J47: =SUM(J40,J45) -> 0 | K47: =SUM(K40,K45) -> 0 | L47: =SUM(L40,L45) -> 0 | M47: =SUM(M40,M45) -> 0
B49: Impôts sur les résultats - IS | H49: =CPC!H63 -> 0 | I49: =CPC!I63 -> 0 | J49: =CPC!J63 -> 0 | K49: =CPC!K63 -> 0 | L49: =CPC!L63 -> 0 | M49: =CPC!M63 -> 0
B51: Résultat net | H51: =SUM(H47,-H49) -> 0 | I51: =SUM(I47,-I49) -> 0 | J51: =SUM(J47,-J49) -> 0 | K51: =SUM(K47,-K49) -> 0 | L51: =SUM(L47,-L49) -> 0 | M51: =SUM(M47,-M49) -> 0
B53: Flux opérationnels | H53: =H34*0.7+H30 -> 0 | I53: =I34*0.7+I30 -> 0 | J53: =J34*0.7+J30 -> 0 | K53: =K34*0.7+K30 -> 0 | L53: =L34*0.7+L30 -> 0 | M53: =M34*0.7+M30 -> 0
B55: Flux nets de trésorerie | H55: =H51+H30 -> 0 | I55: =I51+I30 -> 0 | J55: =J51+J30 -> 0 | K55: =K51+K30 -> 0 | L55: =L51+L30 -> 0 | M55: =M51+M30 -> 0

Sheet 3 (A ne pas supprimer)
A1: =Couverture!G20 -> MaSociété
A2: =IFERROR(MID(CELL("filename",A2),FIND("]",CELL("filename",A2))+1,255),"< - >") -> 3 (A ne pas supprimer)
D5: ANPMExpert: > Merci de renseigner uniquement les dividendes distribués sur la période historique.
D12: =_xlfn.NUMBERVALUE(YPL1)-3 -> 2023 | E12: =D12+1 -> 2024 | F12: =E12+1 -> 2025
B14: Dividendes distribués (en KMAD) | D14: 0 | E14: 0 | F14: 0
B16: Activité
B17: Chiffre d'affaires (en KMAD) | D17: =CPC!D20 -> 0 | E17: =CPC!E20 -> 0 | F17: =CPC!F20 -> 0
B18: Valeur ajoutée (en KMAD) | D18: =SUM(CPC!D20,CPC!D21,-CPC!D26,-CPC!D31,-CPC!D35) -> 0 | E18: =SUM(CPC!E20,CPC!E21,-CPC!E26,-CPC!E31,-CPC!E35) -> 0 | F18: =SUM(CPC!F20,CPC!F21,-CPC!F26,-CPC!F31,-CPC!F35) -> 0
B19: EBE (en KMAD) | D19: =SUM(CPC!D48,CPC!D44) -> 0 | E19: =SUM(CPC!E48,CPC!E44) -> 0 | F19: =SUM(CPC!F48,CPC!F44) -> 0
B20: % Masse salariale / CA | D20: =IFERROR(CPC!D42/CPC!D20, 0) -> 0 | E20: =IFERROR(CPC!E42/CPC!E20, 0) -> 0 | F20: =IFERROR(CPC!F42/CPC!F20, 0) -> 0
B22: Ratios de structure financière
B23: Dettes de financement | D23: =Bilan!D64 -> 0 | E23: =Bilan!E64 -> 0 | F23: =Bilan!F64 -> 0
B24: Capitaux permanents | D24: =Bilan!D58+Bilan!D61+Bilan!D64 -> 0 | E24: =Bilan!E58+Bilan!E61+Bilan!E64 -> 0 | F24: =Bilan!F58+Bilan!F61+Bilan!F64 -> 0
B25: Ratio d'endettement | D25: =IFERROR(+D23/D24, 0) -> 0 | E25: =IFERROR(+E23/E24, 0) -> 0 | F25: =IFERROR(+F23/F24, 0) -> 0
B26: Fonds de roulement (FR) | D26: =+Bilan!D68-Bilan!D27 -> 0 | E26: =+Bilan!E68-Bilan!E27 -> 0 | F26: =+Bilan!F68-Bilan!F27 -> 0
B27: Besoin en fonds de roulement (BFR) | D27: =Bilan!D43-Bilan!D78 -> 0 | E27: =Bilan!E43-Bilan!E78 -> 0 | F27: =Bilan!F43-Bilan!F78 -> 0
B28: % FR/BFR | D28: =IFERROR(D26/D27, 0) -> 0 | E28: =IFERROR(E26/E27, 0) -> 0 | F28: =IFERROR(F26/F27, 0) -> 0
B30: Rentabilité
B31: % EBE /CA | D31: =IFERROR(SUM(CPC!D48,CPC!D44)/CPC!D20, 0) -> 0 | E31: =IFERROR(SUM(CPC!E48,CPC!E44)/CPC!E20, 0) -> 0 | F31: =IFERROR(SUM(CPC!F48,CPC!F44)/CPC!F20, 0) -> 0
B32: % Résultat net / chiffre d'affaires | D32: =IFERROR(SUM(CPC!D65)/CPC!D20, 0) -> 0 | E32: =IFERROR(SUM(CPC!E65)/CPC!E20, 0) -> 0 | F32: =IFERROR(SUM(CPC!F65)/CPC!F20, 0) -> 0
B34: Ratio de trésorerie
B35: Trésorerie nette | D35: =+D26-D27 -> 0 | E35: =+E26-E27 -> 0 | F35: =+F26-F27 -> 0
B36: Rotation des stocks (en jours de CA TTC) | D36: =IFERROR(Bilan!D34*365/(CPC!D20*1.2), 0) -> 0 | E36: =IFERROR(Bilan!E34*365/(CPC!E20*1.2), 0) -> 0 | F36: =IFERROR(Bilan!F34*365/(CPC!F20*1.2), 0) -> 0
B37: Délais clients (en jours de CA TTC) | D37: =IFERROR(Bilan!D34*365/(CPC!D20*1.2), 0) -> 0 | E37: =IFERROR(Bilan!E34*365/(CPC!E20*1.2), 0) -> 0 | F37: =IFERROR(Bilan!F34*365/(CPC!F20*1.2), 0) -> 0
B38: Crédit fournisseurs (en jours d'achats TTC) | D38: =IFERROR(Bilan!D34*365/(SUM(CPC!D26,CPC!D31,CPC!D35)*1.2), 0) -> 0 | E38: =IFERROR(Bilan!E34*365/(SUM(CPC!E26,CPC!E31,CPC!E35)*1.2), 0) -> 0 | F38: =IFERROR(Bilan!F34*365/(SUM(CPC!F26,CPC!F31,CPC!F35)*1.2), 0) -> 0

Sheet Impacts
A1: =Couverture!G20 -> MaSociété | D1: <
A2: =IFERROR(MID(CELL("filename",A2),FIND("]",CELL("filename",A2))+1,255),"< - >") -> Impacts
B5: ANPMExpert: > Les emplois directs à créer doivent correspondre au nombre moyen mensuel par année de salariés déclarés qui seront vérifiés sur l'attestation de CNSS modèle 212-2-44. Il est impératif de renseigner la création prévisionnelle d'emplois directs et indirects en détail et par année.
D11: ="Période historique"&IF(Synthèse!D18="Création"," - Non applicable","") -> Période historique - Non applicable | H11: Période prévisionnelle
B12: Impacts socio-éconcomiques du projet | D12: =_xlfn.NUMBERVALUE(YPL1)-3 -> 2023 | E12: =D12+1 -> 2024 | F12: =E12+1 -> 2025 | H12: =_xlfn.NUMBERVALUE(YPL1) -> 2026 | I12: =H12+1 -> 2027 | J12: =I12+1 -> 2028 | K12: =J12+1 -> 2029 | L12: =K12+1 -> 2030 | M12: =L12+1 -> 2031 | O12: Total
B14: Chiffre d’affaires global (CA) - en KMAD | D14: =CPC!D20 -> 0 | E14: =CPC!E20 -> 0 | F14: =CPC!F20 -> 0 | H14: =CPC!H20 -> 0 | I14: =CPC!I20 -> 0 | J14: =CPC!J20 -> 0 | K14: =CPC!K20 -> 0 | L14: =CPC!L20 -> 0 | M14: =CPC!M20 -> 0 | O14: =SUM(H14:M14) -> 0
B15: dont CA devises* - en KMAD | D15: 0 | E15: 0 | F15: 0 | H15: 0 | I15: 0 | J15: 0 | K15: 0 | L15: 0 | M15: 0 | O15: =SUM(H15:M15) -> 0
O16: =SUM(H16:M16) -> 0
B17: CA lié à la réalisation du projet (CA projet) - en KMAD | H17: =' 2 ((A ne pas supprimer)'!H16 -> 0 | I17: =' 2 ((A ne pas supprimer)'!I16 -> 0 | J17: =' 2 ((A ne pas supprimer)'!J16 -> 0 | K17: =' 2 ((A ne pas supprimer)'!K16 -> 0 | L17: =' 2 ((A ne pas supprimer)'!L16 -> 0 | M17: =' 2 ((A ne pas supprimer)'!M16 -> 0 | O17: =SUM(H17:M17) -> 0
B18: dont CA projet Export - en KMAD | H18: 0 | I18: 0 | J18: 0 | K18: 0 | L18: 0 | M18: 0 | O18: =SUM(H18:M18) -> 0
B19: Valeur ajoutée globale (VA) - en KMAD | D19: =SUM(CPC!F20,CPC!F21,-CPC!F26,-CPC!F31,-CPC!F35) -> 0 | E19: =SUM(CPC!G20,CPC!G21,-CPC!G26,-CPC!G31,-CPC!G35) -> 0 | F19: =SUM(CPC!H20,CPC!H21,-CPC!H26,-CPC!H31,-CPC!H35) -> 0 | H19: =SUM(CPC!J20,CPC!J21,-CPC!J26,-CPC!J31,-CPC!J35) -> 0 | I19: =SUM(CPC!K20,CPC!K21,-CPC!K26,-CPC!K31,-CPC!K35) -> 0 | J19: =SUM(CPC!L20,CPC!L21,-CPC!L26,-CPC!L31,-CPC!L35) -> 0 | K19: =SUM(CPC!M20,CPC!M21,-CPC!M26,-CPC!M31,-CPC!M35) -> 0 | L19: =SUM(CPC!N20,CPC!N21,-CPC!N26,-CPC!N31,-CPC!N35) -> 0 | M19: =SUM(CPC!O20,CPC!O21,-CPC!O26,-CPC!O31,-CPC!O35) -> 0 | O19: =SUM(H19:M19) -> 0
B20: dont VA liée à la réalisation du projet (VA projet) - en KMAD | H20: =SUM(' 2 ((A ne pas supprimer)'!H16,' 2 ((A ne pas supprimer)'!H17,-' 2 ((A ne pas supprimer)'!H22,-' 2 ((A ne pas supprimer)'!H23,-' 2 ((A ne pas supprimer)'!H26) -> 0 | I20: =SUM(' 2 ((A ne pas supprimer)'!I16,' 2 ((A ne pas supprimer)'!I17,-' 2 ((A ne pas supprimer)'!I22,-' 2 ((A ne pas supprimer)'!I23,-' 2 ((A ne pas supprimer)'!I26) -> 0 | J20: =SUM(' 2 ((A ne pas supprimer)'!J16,' 2 ((A ne pas supprimer)'!J17,-' 2 ((A ne pas supprimer)'!J22,-' 2 ((A ne pas supprimer)'!J23,-' 2 ((A ne pas supprimer)'!J26) -> 0 | K20: =SUM(' 2 ((A ne pas supprimer)'!K16,' 2 ((A ne pas supprimer)'!K17,-' 2 ((A ne pas supprimer)'!K22,-' 2 ((A ne pas supprimer)'!K23,-' 2 ((A ne pas supprimer)'!K26) -> 0 | L20: =SUM(' 2 ((A ne pas supprimer)'!L16,' 2 ((A ne pas supprimer)'!L17,-' 2 ((A ne pas supprimer)'!L22,-' 2 ((A ne pas supprimer)'!L23,-' 2 ((A ne pas supprimer)'!L26) -> 0 | M20: =SUM(' 2 ((A ne pas supprimer)'!M16,' 2 ((A ne pas supprimer)'!M17,-' 2 ((A ne pas supprimer)'!M22,-' 2 ((A ne pas supprimer)'!M23,-' 2 ((A ne pas supprimer)'!M26) -> 0 | O20: =SUM(H20:M20) -> 0
B21: Résultat net global - en KMAD | D21: =CPC!D65 -> 0 | E21: =CPC!E65 -> 0 | F21: =CPC!F65 -> 0 | H21: =CPC!H65 -> 0 | I21: =CPC!I65 -> 0 | J21: =CPC!J65 -> 0 | K21: =CPC!K65 -> 0 | L21: =CPC!L65 -> 0 | M21: =CPC!M65 -> 0 | O21: =SUM(H21:M21) -> 0
B22: en % du CA | D22: =IFERROR(D21/D14, 0) -> 0 | E22: =IFERROR(E21/E14, 0) -> 0 | F22: =IFERROR(F21/F14, 0) -> 0 | H22: =IFERROR(H21/H14, 0) -> 0 | I22: =IFERROR(I21/I14, 0) -> 0 | J22: =IFERROR(J21/J14, 0) -> 0 | K22: =IFERROR(K21/K14, 0) -> 0 | L22: =IFERROR(L21/L14, 0) -> 0 | M22: =IFERROR(M21/M14, 0) -> 0 | O22: =IFERROR(O21/O14, 0) -> 0
B26: Emplois permenants à créer** | H26: 0 | I26: 0 | J26: 0 | K26: 0 | L26: 0 | M26: 0 | O26: =SUM(H26:M26) -> 0
B27: Emplois intérimaires à créer | H27: 0 | I27: 0 | J27: 0 | K27: 0 | L27: 0 | M27: 0 | O27: =SUM(H27:M27) -> 0
B29: Effectif total direct cumulé | D29: 0 | E29: 0 | F29: 0 | H29: =F29+SUM(H26:H27) -> 0 | I29: =H29+SUM(I26:I27) -> 0 | J29: =I29+SUM(J26:J27) -> 0 | K29: =J29+SUM(K26:K27) -> 0 | L29: =K29+SUM(L26:L27) -> 0 | M29: =L29+SUM(M26:M27) -> 0 | O29: =M29 -> 0
B31: > Emplois indirects à créer | H31: 0 | I31: 0 | J31: 0 | K31: 0 | L31: 0 | M31: 0 | O31: =SUM(H31:M31) -> 0
B33: (*) Recettes en devises (1 EUR = 11 MAD, 1 USD = 10 MAD)
B34: (**) Hors intérimaires

Sheet Indicateurs financiers prév.
A1: =Couverture!G20 -> MaSociété
A2: =IFERROR(MID(CELL("filename",A2),FIND("]",CELL("filename",A2))+1,255),"< - >") -> Indicateurs financiers prév.
C3: ANPMExpert: > Aucune intervention n'est sollicitée sur cette feuille.
H10: Période prévisionnelle
H11: =_xlfn.NUMBERVALUE(YPL1) -> 2026 | I11: =H11+1 -> 2027 | J11: =I11+1 -> 2028 | K11: =J11+1 -> 2029 | L11: =K11+1 -> 2030 | M11: =L11+1 -> 2031
B13: Activité
B14: Chiffre d'affaires (en KMAD) | H14: =CPC!H20 -> 0 | I14: =CPC!I20 -> 0 | J14: =CPC!J20 -> 0 | K14: =CPC!K20 -> 0 | L14: =CPC!L20 -> 0 | M14: =CPC!M20 -> 0
B15: Valeur ajoutée (en KMAD) | H15: =SUM(CPC!H20,CPC!H21,-CPC!H31,-CPC!H35) -> 0 | I15: =SUM(CPC!I20,CPC!I21,-CPC!I31,-CPC!I35) -> 0 | J15: =SUM(CPC!J20,CPC!J21,-CPC!J31,-CPC!J35) -> 0 | K15: =SUM(CPC!K20,CPC!K21,-CPC!K31,-CPC!K35) -> 0 | L15: =SUM(CPC!L20,CPC!L21,-CPC!L31,-CPC!L35) -> 0 | M15: =SUM(CPC!M20,CPC!M21,-CPC!M31,-CPC!M35) -> 0
B16: EBE (en KMAD) | H16: =SUM(CPC!H48,CPC!H44) -> 0 | I16: =SUM(CPC!I48,CPC!I44) -> 0 | J16: =SUM(CPC!J48,CPC!J44) -> 0 | K16: =SUM(CPC!K48,CPC!K44) -> 0 | L16: =SUM(CPC!L48,CPC!L44) -> 0 | M16: =SUM(CPC!M48,CPC!M44) -> 0
B17: % Masse salariale / CA | H17: =IFERROR(CPC!H42/CPC!H20, 0) -> 0 | I17: =IFERROR(CPC!I42/CPC!I20, 0) -> 0 | J17: =IFERROR(CPC!J42/CPC!J20, 0) -> 0 | K17: =IFERROR(CPC!K42/CPC!K20, 0) -> 0 | L17: =IFERROR(CPC!L42/CPC!L20, 0) -> 0 | M17: =IFERROR(CPC!M42/CPC!M20, 0) -> 0
B19: Ratios de structure financière
B20: Dettes de financement | H20: =Bilan!H64 -> 0 | I20: =Bilan!I64 -> 0 | J20: =Bilan!J64 -> 0 | K20: =Bilan!K64 -> 0 | L20: =Bilan!L64 -> 0 | M20: =Bilan!M64 -> 0
B21: Capitaux permanents | H21: =Bilan!H58+Bilan!H61+Bilan!H64 -> 0 | I21: =Bilan!I58+Bilan!I61+Bilan!I64 -> 0 | J21: =Bilan!J58+Bilan!J61+Bilan!J64 -> 0 | K21: =Bilan!K58+Bilan!K61+Bilan!K64 -> 0 | L21: =Bilan!L58+Bilan!L61+Bilan!L64 -> 0 | M21: =Bilan!M58+Bilan!M61+Bilan!M64 -> 0
B22: Ratio d'endettement | H22: =IFERROR(+H20/H21, 0) -> 0 | I22: =IFERROR(+I20/I21, 0) -> 0 | J22: =IFERROR(+J20/J21, 0) -> 0 | K22: =IFERROR(+K20/K21, 0) -> 0 | L22: =IFERROR(+L20/L21, 0) -> 0 | M22: =IFERROR(+M20/M21, 0) -> 0
B23: Fonds de roulement (FR) | H23: =+Bilan!H68-Bilan!H27 -> 0 | I23: =+Bilan!I68-Bilan!I27 -> 0 | J23: =+Bilan!J68-Bilan!J27 -> 0 | K23: =+Bilan!K68-Bilan!K27 -> 0 | L23: =+Bilan!L68-Bilan!L27 -> 0 | M23: =+Bilan!M68-Bilan!M27 -> 0
B24: Besoin en fonds de roulement (BFR) | H24: =Bilan!H43-Bilan!H78 -> 0 | I24: =Bilan!I43-Bilan!I78 -> 0 | J24: =Bilan!J43-Bilan!J78 -> 0 | K24: =Bilan!K43-Bilan!K78 -> 0 | L24: =Bilan!L43-Bilan!L78 -> 0 | M24: =Bilan!M43-Bilan!M78 -> 0
B25: % FR/BFR | H25: =IFERROR(H23/H24, 0) -> 0 | I25: =IFERROR(I23/I24, 0) -> 0 | J25: =IFERROR(J23/J24, 0) -> 0 | K25: =IFERROR(K23/K24, 0) -> 0 | L25: =IFERROR(L23/L24, 0) -> 0 | M25: =IFERROR(M23/M24, 0) -> 0
B27: Rentabilité
B28: % EBE /CA | H28: =IFERROR(SUM(CPC!H48,CPC!H44)/CPC!H20, 0) -> 0 | I28: =IFERROR(SUM(CPC!I48,CPC!I44)/CPC!I20, 0) -> 0 | J28: =IFERROR(SUM(CPC!J48,CPC!J44)/CPC!J20, 0) -> 0 | K28: =IFERROR(SUM(CPC!K48,CPC!K44)/CPC!K20, 0) -> 0 | L28: =IFERROR(SUM(CPC!L48,CPC!L44)/CPC!L20, 0) -> 0 | M28: =IFERROR(SUM(CPC!M48,CPC!M44)/CPC!M20, 0) -> 0
B29: % Résultat net / chiffre d'affaires | H29: =IFERROR(SUM(CPC!H65)/CPC!H20, 0) -> 0 | I29: =IFERROR(SUM(CPC!I65)/CPC!I20, 0) -> 0 | J29: =IFERROR(SUM(CPC!J65)/CPC!J20, 0) -> 0 | K29: =IFERROR(SUM(CPC!K65)/CPC!K20, 0) -> 0 | L29: =IFERROR(SUM(CPC!L65)/CPC!L20, 0) -> 0 | M29: =IFERROR(SUM(CPC!M65)/CPC!M20, 0) -> 0
B31: Ratio de trésorerie
B32: Trésorerie nette | H32: =+H23-H24 -> 0 | I32: =+I23-I24 -> 0 | J32: =+J23-J24 -> 0 | K32: =+K23-K24 -> 0 | L32: =+L23-L24 -> 0 | M32: =+M23-M24 -> 0
B33: Rotation des stocks (en jours de CA TTC) | H33: =IFERROR(Bilan!H34*365/(CPC!H20*1.2), 0) -> 0 | I33: =IFERROR(Bilan!I34*365/(CPC!I20*1.2), 0) -> 0 | J33: =IFERROR(Bilan!J34*365/(CPC!J20*1.2), 0) -> 0 | K33: =IFERROR(Bilan!K34*365/(CPC!K20*1.2), 0) -> 0 | L33: =IFERROR(Bilan!L34*365/(CPC!L20*1.2), 0) -> 0 | M33: =IFERROR(Bilan!M34*365/(CPC!M20*1.2), 0) -> 0
B34: Délais clients (en jours de CA TTC) | H34: =IFERROR(SUM(Bilan!H36,-Bilan!H71)*365/(CPC!H20*1.2), 0) -> 0 | I34: =IFERROR(SUM(Bilan!I36,-Bilan!I71)*365/(CPC!I20*1.2), 0) -> 0 | J34: =IFERROR(SUM(Bilan!J36,-Bilan!J71)*365/(CPC!J20*1.2), 0) -> 0 | K34: =IFERROR(SUM(Bilan!K36,-Bilan!K71)*365/(CPC!K20*1.2), 0) -> 0 | L34: =IFERROR(SUM(Bilan!L36,-Bilan!L71)*365/(CPC!L20*1.2), 0) -> 0 | M34: =IFERROR(SUM(Bilan!M36,-Bilan!M71)*365/(CPC!M20*1.2), 0) -> 0
B35: Dettes fournisseurs (en jours d'achats TTC) | H35: =IFERROR(SUM(Bilan!H70,-Bilan!H35)*365/(SUM(,CPC!H31,CPC!H35)*1.2), 0) -> 0 | I35: =IFERROR(SUM(Bilan!I70,-Bilan!I35)*365/(SUM(,CPC!I31,CPC!I35)*1.2), 0) -> 0 | J35: =IFERROR(SUM(Bilan!J70,-Bilan!J35)*365/(SUM(,CPC!J31,CPC!J35)*1.2), 0) -> 0 | K35: =IFERROR(SUM(Bilan!K70,-Bilan!K35)*365/(SUM(,CPC!K31,CPC!K35)*1.2), 0) -> 0 | L35: =IFERROR(SUM(Bilan!L70,-Bilan!L35)*365/(SUM(,CPC!L31,CPC!L35)*1.2), 0) -> 0 | M35: =IFERROR(SUM(Bilan!M70,-Bilan!M35)*365/(SUM(,CPC!M31,CPC!M35)*1.2), 0) -> 0

Sheet TFT
A1: =Couverture!G20 -> MaSociété
A2: =IFERROR(MID(CELL("filename",A2),FIND("]",CELL("filename",A2))+1,255),"< - >") -> TFT
B5: ANPMExpert: > Aucune intervention n'est sollicitée sur cette feuille.
D11: ="Période historique"&IF(Synthèse!D18="Création"," - Non applicable","") -> Période historique - Non applicable | H11: Période prévisionnelle
B12: TFT (en KMAD) | D12: =_xlfn.NUMBERVALUE(YPL1)-3 -> 2023 | E12: =D12+1 -> 2024 | F12: =E12+1 -> 2025 | H12: =_xlfn.NUMBERVALUE(YPL1) -> 2026 | I12: =H12+1 -> 2027 | J12: =I12+1 -> 2028 | K12: =J12+1 -> 2029 | L12: =K12+1 -> 2030 | M12: =L12+1 -> 2031
B14: (+) Capacité d'autofinancement | H14: =CPC!H80 -> 0 | I14: =CPC!I80 -> 0 | J14: =CPC!J80 -> 0 | K14: =CPC!K80 -> 0 | L14: =CPC!L80 -> 0 | M14: =CPC!M80 -> 0
B15: (-) Variation du BFR global* | H15: =SUM(((Bilan!H43-Bilan!H37)-(Bilan!H78-Bilan!H72)))-SUM(((Bilan!F43-Bilan!F37)-(Bilan!F78-Bilan!F72))) -> 0 | I15: =SUM(((Bilan!I43-Bilan!I37)-(Bilan!I78-Bilan!I72)))-SUM(((Bilan!H43-Bilan!H37)-(Bilan!H78-Bilan!H72))) -> 0 | J15: =SUM(((Bilan!J43-Bilan!J37)-(Bilan!J78-Bilan!J72)))-SUM(((Bilan!I43-Bilan!I37)-(Bilan!I78-Bilan!I72))) -> 0 | K15: =SUM(((Bilan!K43-Bilan!K37)-(Bilan!K78-Bilan!K72)))-SUM(((Bilan!J43-Bilan!J37)-(Bilan!J78-Bilan!J72))) -> 0 | L15: =SUM(((Bilan!L43-Bilan!L37)-(Bilan!L78-Bilan!L72)))-SUM(((Bilan!K43-Bilan!K37)-(Bilan!K78-Bilan!K72))) -> 0 | M15: =SUM(((Bilan!M43-Bilan!M37)-(Bilan!M78-Bilan!M72)))-SUM(((Bilan!L43-Bilan!L37)-(Bilan!L78-Bilan!L72))) -> 0
B17: Opérationnel (a) | H17: =H14-H15 -> 0 | I17: =I14-I15 -> 0 | J17: =J14-J15 -> 0 | K17: =K14-K15 -> 0 | L17: =L14-L15 -> 0 | M17: =M14-M15 -> 0
B19: (-) Dépenses d'investissements | H19: =+'Synthèse du PI'!E25 -> 0 | I19: =+'Synthèse du PI'!F25 -> 0 | J19: =+'Synthèse du PI'!G25 -> 0 | K19: =+'Synthèse du PI'!H25 -> 0
B20: (+) Subventions d'investissement | H20: =+'Mode de financement'!G26 -> 0 | I20: =+'Mode de financement'!H26 -> 0 | J20: =+'Mode de financement'!I26 -> 0 | K20: =+'Mode de financement'!J26 -> 0 | L20: =+'Mode de financement'!K26 -> 0
B22: Investissement (b) | H22: =H20-H19 -> 0 | I22: =I20-I19 -> 0 | J22: =J20-J19 -> 0 | K22: =K20-K19 -> 0 | L22: =L20-L19 -> 0 | M22: =M20-M19 -> 0
B24: (-) Distribution de bénéfices | H24: =SUM(Bilan!H54:H55)-SUM(Bilan!F54:F57) -> 0 | I24: =SUM(Bilan!I54:I55)-SUM(Bilan!H54:H57) -> 0 | J24: =SUM(Bilan!J54:J55)-SUM(Bilan!I54:I57) -> 0 | K24: =SUM(Bilan!K54:K55)-SUM(Bilan!J54:J57) -> 0 | L24: =SUM(Bilan!L54:L55)-SUM(Bilan!K54:K57) -> 0 | M24: =SUM(Bilan!M54:M55)-SUM(Bilan!L54:L57) -> 0
B25: (+) Variation des fonds propres** | H25: =SUM(Bilan!H51:H53,Bilan!H72,-Bilan!H37)-SUM(Bilan!F51:F53,Bilan!F72,-Bilan!F37) -> 0 | I25: =SUM(Bilan!I51:I53,Bilan!I72,-Bilan!I37)-SUM(Bilan!H51:H53,Bilan!H72,-Bilan!H37) -> 0 | J25: =SUM(Bilan!J51:J53,Bilan!J72,-Bilan!J37)-SUM(Bilan!I51:I53,Bilan!I72,-Bilan!I37) -> 0 | K25: =SUM(Bilan!K51:K53,Bilan!K72,-Bilan!K37)-SUM(Bilan!J51:J53,Bilan!J72,-Bilan!J37) -> 0 | L25: =SUM(Bilan!L51:L53,Bilan!L72,-Bilan!L37)-SUM(Bilan!K51:K53,Bilan!K72,-Bilan!K37) -> 0 | M25: =SUM(Bilan!M51:M53,Bilan!M72,-Bilan!M37)-SUM(Bilan!L51:L53,Bilan!L72,-Bilan!L37) -> 0
B26: (-) Variation de la dette | H26: =Bilan!H64-Bilan!F64 -> 0 | I26: =Bilan!I64-Bilan!H64 -> 0 | J26: =Bilan!J64-Bilan!I64 -> 0 | K26: =Bilan!K64-Bilan!J64 -> 0 | L26: =Bilan!L64-Bilan!K64 -> 0 | M26: =Bilan!M64-Bilan!L64 -> 0
B28: Financement (c) | H28: =-H24+H25-H26 -> 0 | I28: =-I24+I25-I26 -> 0 | J28: =-J24+J25-J26 -> 0 | K28: =-K24+K25-K26 -> 0 | L28: =-L24+L25-L26 -> 0 | M28: =-M24+M25-M26 -> 0
B30: Flux de trésorerie (a) + (b) + (c) | H30: =SUM(H17,H22,H28) -> 0 | I30: =SUM(I17,I22,I28) -> 0 | J30: =SUM(J17,J22,J28) -> 0 | K30: =SUM(K17,K22,K28) -> 0 | L30: =SUM(L17,L22,L28) -> 0 | M30: =SUM(M17,M22,M28) -> 0
B32: Trésorerie initiale | H32: =SUM(Bilan!F45,-Bilan!F80) -> 0 | I32: =H36 -> 0 | J32: =I36 -> 0 | K32: =J36 -> 0 | L32: =K36 -> 0 | M32: =L36 -> 0
B34: Flux de trésorerie | H34: =H30 -> 0 | I34: =I30 -> 0 | J34: =J30 -> 0 | K34: =K30 -> 0 | L34: =L30 -> 0 | M34: =M30 -> 0
B36: Trésorerie finale | H36: =SUM(H32,H34) -> 0 | I36: =SUM(I32,I34) -> 0 | J36: =SUM(J32,J34) -> 0 | K36: =SUM(K32,K34) -> 0 | L36: =SUM(L32,L34) -> 0 | M36: =SUM(M32,M34) -> 0
B38: * Hors comptes courants d'associés
B39: ** Incl. quasi fonds propres (y compris comptes courants d'associés)

Sheet Variation du BFR
A1: =Couverture!G20 -> MaSociété
A2: =IFERROR(MID(CELL("filename",A2),FIND("]",CELL("filename",A2))+1,255),"< - >") -> Variation du BFR
B5: ANPMExpert: > Aucune intervention n'est sollicitée sur cette feuille.
D13: ="Période historique"&IF(Synthèse!D20="Création"," - Non applicable","") -> Période historique | H13: Période prévisionnelle
B14: Variation du BFR (en KMAD) | D14: =_xlfn.NUMBERVALUE(YPL1)-3 -> 2023 | E14: =D14+1 -> 2024 | F14: =E14+1 -> 2025 | H14: =_xlfn.NUMBERVALUE(YPL1) -> 2026 | I14: =H14+1 -> 2027 | J14: =I14+1 -> 2028 | K14: =J14+1 -> 2029 | L14: =K14+1 -> 2030 | M14: =L14+1 -> 2031
B16: Actif circulant 1 | D16: =SUM(Bilan!D43,-Bilan!D41,-Bilan!D40,-Bilan!D37) -> 0 | E16: =SUM(Bilan!E43,-Bilan!E41,-Bilan!E40,-Bilan!E37) -> 0 | F16: =SUM(Bilan!F43,-Bilan!F41,-Bilan!F40,-Bilan!F37) -> 0 | H16: =SUM(Bilan!H43,-Bilan!H41,-Bilan!H40,-Bilan!H37) -> 0 | I16: =SUM(Bilan!I43,-Bilan!I41,-Bilan!I40,-Bilan!I37) -> 0 | J16: =SUM(Bilan!J43,-Bilan!J41,-Bilan!J40,-Bilan!J37) -> 0 | K16: =SUM(Bilan!K43,-Bilan!K41,-Bilan!K40,-Bilan!K37) -> 0 | L16: =SUM(Bilan!L43,-Bilan!L41,-Bilan!L40,-Bilan!L37) -> 0 | M16: =SUM(Bilan!M43,-Bilan!M41,-Bilan!M40,-Bilan!M37) -> 0
B17: Passif circulant 2 | D17: =SUM(Bilan!D78,-Bilan!D76,-Bilan!D75,-Bilan!D72) -> 0 | E17: =SUM(Bilan!E78,-Bilan!E76,-Bilan!E75,-Bilan!E72) -> 0 | F17: =SUM(Bilan!F78,-Bilan!F76,-Bilan!F75,-Bilan!F72) -> 0 | H17: =SUM(Bilan!H78,-Bilan!H76,-Bilan!H75,-Bilan!H72) -> 0 | I17: =SUM(Bilan!I78,-Bilan!I76,-Bilan!I75,-Bilan!I72) -> 0 | J17: =SUM(Bilan!J78,-Bilan!J76,-Bilan!J75,-Bilan!J72) -> 0 | K17: =SUM(Bilan!K78,-Bilan!K76,-Bilan!K75,-Bilan!K72) -> 0 | L17: =SUM(Bilan!L78,-Bilan!L76,-Bilan!L75,-Bilan!L72) -> 0 | M17: =SUM(Bilan!M78,-Bilan!M76,-Bilan!M75,-Bilan!M72) -> 0
B19: BFR | D19: =SUM(D16,-D17) -> 0 | E19: =SUM(E16,-E17) -> 0 | F19: =SUM(F16,-F17) -> 0 | H19: =SUM(H16,-H17) -> 0 | I19: =SUM(I16,-I17) -> 0 | J19: =SUM(J16,-J17) -> 0 | K19: =SUM(K16,-K17) -> 0 | L19: =SUM(L16,-L17) -> 0 | M19: =SUM(M16,-M17) -> 0
B21: Var. BFR | E21: =E19-D19 -> 0 | F21: =F19-E19 -> 0 | H21: =H19-F19 -> 0 | I21: =I19-H19 -> 0 | J21: =J19-I19 -> 0 | K21: =K19-J19 -> 0 | L21: =L19-K19 -> 0 | M21: =M19-L19 -> 0
B23: Var. BFR cumulé | H23: =SUM($H$21:H21) -> 0 | I23: =SUM($H$21:I21) -> 0 | J23: =SUM($H$21:J21) -> 0 | K23: =SUM($H$21:K21) -> 0 | L23: =SUM($H$21:L21) -> 0 | M23: =SUM($H$21:M21) -> 0
B25: 1 Actif circulant : diminué des titres et autres valeurs de placement et des écarts de conversion
B26: 2 Passif circulant : diminué des comptes d'associés, des écarts de conversion et des autres provisions

Sheet TRI
A1: =Couverture!G20 -> MaSociété
A2: =IFERROR(MID(CELL("filename",A2),FIND("]",CELL("filename",A2))+1,255),"< - >") -> TRI
D4: ANPMExpert: > Aucune intervention n'est sollicitée sur cette feuille.
H10: Période prévisionnelle
B11: FTD (en KMAD) | H11: =_xlfn.NUMBERVALUE(YPL1) -> 2026 | I11: =H11+1 -> 2027 | J11: =I11+1 -> 2028 | K11: =J11+1 -> 2029 | L11: =K11+1 -> 2030 | M11: =L11+1 -> 2031
B13: Résultat d'exploitation* | H13: =' 2 ((A ne pas supprimer)'!H34-' 2 ((A ne pas supprimer)'!H24 -> 0 | I13: =' 2 ((A ne pas supprimer)'!I34-' 2 ((A ne pas supprimer)'!I24 -> 0 | J13: =' 2 ((A ne pas supprimer)'!J34-' 2 ((A ne pas supprimer)'!J24 -> 0 | K13: =' 2 ((A ne pas supprimer)'!K34-' 2 ((A ne pas supprimer)'!K24 -> 0 | L13: =' 2 ((A ne pas supprimer)'!L34-' 2 ((A ne pas supprimer)'!L24 -> 0 | M13: =' 2 ((A ne pas supprimer)'!M34-' 2 ((A ne pas supprimer)'!M24 -> 0
B14: IS théorique / Résultat d'exploitation | H14: =IF(H13<0,0.5%*' 2 ((A ne pas supprimer)'!H16,IF(H13<'1 (A ne pas supprimer)'!$E$46,'1 (A ne pas supprimer)'!F46*H13,IF(H13<'1 (A ne pas supprimer)'!$E$47,'1 (A ne pas supprimer)'!F47*H13,IF(H13<'1 (A ne pas supprimer)'!$E$48,'1 (A ne pas supprimer)'!F48*H13,'1 (A ne pas supprimer)'!F49*H13)))) -> 0 | I14: =IF(I13<0,0.5%*' 2 ((A ne pas supprimer)'!I16,IF(I13<'1 (A ne pas supprimer)'!$E$46,'1 (A ne pas supprimer)'!G46*I13,IF(I13<'1 (A ne pas supprimer)'!$E$47,'1 (A ne pas supprimer)'!G47*I13,IF(I13<'1 (A ne pas supprimer)'!$E$48,'1 (A ne pas supprimer)'!G48*I13,'1 (A ne pas supprimer)'!G49*I13)))) -> 0 | J14: =IF(J13<0,0.5%*' 2 ((A ne pas supprimer)'!J16,IF(J13<'1 (A ne pas supprimer)'!$E$46,'1 (A ne pas supprimer)'!H46*J13,IF(J13<'1 (A ne pas supprimer)'!$E$47,'1 (A ne pas supprimer)'!H47*J13,IF(J13<'1 (A ne pas supprimer)'!$E$48,'1 (A ne pas supprimer)'!H48*J13,'1 (A ne pas supprimer)'!H49*J13)))) -> 0 | K14: =IF(K13<0,0.5%*' 2 ((A ne pas supprimer)'!K16,IF(K13<'1 (A ne pas supprimer)'!$E$46,'1 (A ne pas supprimer)'!I46*K13,IF(K13<'1 (A ne pas supprimer)'!$E$47,'1 (A ne pas supprimer)'!I47*K13,IF(K13<'1 (A ne pas supprimer)'!$E$48,'1 (A ne pas supprimer)'!I48*K13,'1 (A ne pas supprimer)'!I49*K13)))) -> 0 | L14: =IF(L13<0,0.5%*' 2 ((A ne pas supprimer)'!L16,IF(L13<'1 (A ne pas supprimer)'!$E$46,'1 (A ne pas supprimer)'!J46*L13,IF(L13<'1 (A ne pas supprimer)'!$E$47,'1 (A ne pas supprimer)'!J47*L13,IF(L13<'1 (A ne pas supprimer)'!$E$48,'1 (A ne pas supprimer)'!J48*L13,'1 (A ne pas supprimer)'!J49*L13)))) -> 0 | M14: =IF(M13<0,0.5%*' 2 ((A ne pas supprimer)'!M16,IF(M13<'1 (A ne pas supprimer)'!$E$46,'1 (A ne pas supprimer)'!K46*M13,IF(M13<'1 (A ne pas supprimer)'!$E$47,'1 (A ne pas supprimer)'!K47*M13,IF(M13<'1 (A ne pas supprimer)'!$E$48,'1 (A ne pas supprimer)'!K48*M13,'1 (A ne pas supprimer)'!K49*M13)))) -> 0
B15: Résultat d'exploitation, net d'IS | H15: =H13-H14 -> 0 | I15: =+I13-I14 -> 0 | J15: =+J13-J14 -> 0 | K15: =+K13-K14 -> 0 | L15: =+L13-L14 -> 0 | M15: =+M13-M14 -> 0
B17: Amortissements | H17: =' 2 ((A ne pas supprimer)'!H30 -> 0 | I17: =' 2 ((A ne pas supprimer)'!I30 -> 0 | J17: =' 2 ((A ne pas supprimer)'!J30 -> 0 | K17: =' 2 ((A ne pas supprimer)'!K30 -> 0 | L17: =' 2 ((A ne pas supprimer)'!L30 -> 0 | M17: =' 2 ((A ne pas supprimer)'!M30 -> 0
B18: Investissements | H18: ='Synthèse du PI'!E25 -> 0 | I18: ='Synthèse du PI'!F25 -> 0 | J18: ='Synthèse du PI'!G25 -> 0 | K18: ='Synthèse du PI'!H25 -> 0
B19: Variation de BFR** | H19: =IFERROR('Variation du BFR'!H21*(' 2 ((A ne pas supprimer)'!H16/CPC!H20), 0) -> 0 | I19: =IFERROR('Variation du BFR'!I21*(' 2 ((A ne pas supprimer)'!I16/CPC!I20), 0) -> 0 | J19: =IFERROR('Variation du BFR'!J21*(' 2 ((A ne pas supprimer)'!J16/CPC!J20), 0) -> 0 | K19: =IFERROR('Variation du BFR'!K21*(' 2 ((A ne pas supprimer)'!K16/CPC!K20), 0) -> 0 | L19: =IFERROR('Variation du BFR'!L21*(' 2 ((A ne pas supprimer)'!L16/CPC!L20), 0) -> 0 | M19: =IFERROR('Variation du BFR'!M21*(' 2 ((A ne pas supprimer)'!M16/CPC!M20), 0) -> 0
B21: Flux de trésorerie disponible | H21: =SUM(H15,H17,-H18,-H19) -> 0 | I21: =SUM(I15,I17,-I18,-I19) -> 0 | J21: =SUM(J15,J17,-J18,-J19) -> 0 | K21: =SUM(K15,K17,-K18,-K19) -> 0 | L21: =SUM(L15,L17,-L18,-L19) -> 0 | M21: =SUM(M15,M17,-M18,-M19) -> 0
